Workbook

Sheet Management Dashboard
A1: EXECUTIVE PAYROLL & ADVANCE MANAGEMENT DASHBOARD
B3: TOTAL ACTIVE STAFF | D3: TOTAL MONTHLY PAYOUT | F3: TOTAL ADVANCE RECOVERED
B4: =COUNTA('Salary Engine'!A3:A500) -> 73 | D4: =SUM('Salary Engine'!O3:O500) -> 2976865 | F4: =SUM('Salary Engine'!N3:N500) -> 0
B7: DESIGNATION SUMMARY
B8: Designation | C8: Staff Count | D8: Total Net Payout
B9: Driver | C9: =COUNTIF('Salary Engine'!C3:C500, "Driver") -> 53 | D9: =SUMIF('Salary Engine'!C3:C500, "Driver", 'Salary Engine'!O3:O500) -> 1886865
B10: Supervisor | C10: =COUNTIF('Salary Engine'!C3:C500, "Supervisor") -> 1 | D10: =SUMIF('Salary Engine'!C3:C500, "Supervisor", 'Salary Engine'!O3:O500) -> 45000
B11: Officer | C11: =COUNTIF('Salary Engine'!C3:C500, "Officer") -> 3 | D11: =SUMIF('Salary Engine'!C3:C500, "Officer", 'Salary Engine'!O3:O500) -> 165000

Sheet Salary Slip
A1: AUTOMATED SALARY SLIP SYSTEM
A3: Select Employee ID: | B3: EMP39
A5: EMPLOYEE DETAILS
A6: Employee ID: | B6: =B3 -> EMP39 | D6: Total Present Days: | E6: =VLOOKUP(B3, 'Salary Engine'!A:O, 4, FALSE) -> 20
A7: Employee Name: | B7: =VLOOKUP(B3, 'Salary Engine'!A:O, 2, FALSE) -> Doulat Khan | D7: Total Absent Days: | E7: =VLOOKUP(B3, 'Salary Engine'!A:O, 5, FALSE) -> 6
A8: Designation: | B8: =VLOOKUP(B3, 'Salary Engine'!A:O, 3, FALSE) -> Driver | D8: Total Sundays/Off: | E8: =VLOOKUP(B3, 'Salary Engine'!A:O, 6, FALSE) -> 4
A10: EARNINGS BREAKDOWN | B10: AMOUNT | D10: ADVANCE & DEDUCTIONS | E10: AMOUNT
A11: Scheduled Base Salary | B11: =VLOOKUP(B3, 'Salary Engine'!A:O, 7, FALSE) -> 25000 | D11: Previous Advance Balance | E11: =VLOOKUP(B3, 'Salary Engine'!A:O, 12, FALSE) -> 0
A12: Absent Deduction (Base) | B12: =-1*(VLOOKUP(B3, 'Salary Engine'!A:O, 5, FALSE)*VLOOKUP(B3, 'Salary Engine'!A:O, 8, FALSE)) -> -4998 | D12: New Advance Taken | E12: =VLOOKUP(B3, 'Salary Engine'!A:O, 13, FALSE) -> 0
A13: Driver Attendance Allowance | B13: =VLOOKUP(B3, 'Salary Engine'!A:O, 10, FALSE) -> 10000 | D13: This Month Advance Return | E13: =VLOOKUP(B3, 'Salary Engine'!A:O, 14, FALSE) -> 0
A14: Total Gross Salary | B14: =VLOOKUP(B3, 'Salary Engine'!A:O, 11, FALSE) -> 30002
A16: NET PAYABLE TO EMPLOYEE | B16: =VLOOKUP(B3, 'Salary Engine'!A:O, 15, FALSE) -> 30002

Sheet Salary Engine
A1: EMPLOYEE SALARY ENGINE WITH SUNDAY PAID-OFF & DRIVER ALLOWANCE LOGIC
A2: Emp ID | B2: Employee Name | C2: Designation | D2: Present Days | E2: Absent Days | F2: Sundays | G2: Base / Fixed Salary | H2: Per Day Rate | I2: Earned Base Salary | J2: Attendance Allowance (Drivers) | K2: Total Gross Salary | L2: Previous Advance | M2: New Advance Taken | N2: Advance Deduction | O2: Net Payable Salary | P2: Status
A3: EMP001 | B3: Shakeel Ayub | C3: Officer | D3: ='Attendance Sheet'!AJ4 -> 26 | E3: ='Attendance Sheet'!AK4 -> 0 | F3: ='Attendance Sheet'!AL4 -> 4 | G3: =IF(C3="Driver", 25000, IF(C3="Supervisor", 45000, 55000)) -> 55000 | H3: =ROUND(G3/30, 0) -> 1833 | I3: =G3-(E3*H3) -> 55000 | J3: =IF(C3="Driver", D3*500, 0) -> 0 | K3: =I3+J3 -> 55000 | L3: 0 | M3: 0 | N3: 0 | O3: =K3-N3 -> 55000 | P3: Active
A4: EMP002 | B4: Kamal UL Haq | C4: Officer | D4: ='Attendance Sheet'!AJ5 -> 26 | E4: ='Attendance Sheet'!AK5 -> 0 | F4: ='Attendance Sheet'!AL5 -> 4 | G4: =IF(C4="Driver", 25000, IF(C4="Supervisor", 45000, 55000)) -> 55000 | H4: =ROUND(G4/30, 0) -> 1833 | I4: =G4-(E4*H4) -> 55000 | J4: =IF(C4="Driver", D4*500, 0) -> 0 | K4: =I4+J4 -> 55000 | L4: 0 | M4: 0 | N4: 0 | O4: =K4-N4 -> 55000 | P4: Active
A5: EMP003 | B5: Ishaq Khan | C5: Officer | D5: ='Attendance Sheet'!AJ6 -> 26 | E5: ='Attendance Sheet'!AK6 -> 0 | F5: ='Attendance Sheet'!AL6 -> 4 | G5: =IF(C5="Driver", 25000, IF(C5="Supervisor", 45000, 55000)) -> 55000 | H5: =ROUND(G5/30, 0) -> 1833 | I5: =G5-(E5*H5) -> 55000 | J5: =IF(C5="Driver", D5*500, 0) -> 0 | K5: =I5+J5 -> 55000 | L5: 0 | M5: 0 | N5: 0 | O5: =K5-N5 -> 55000 | P5: Active
A6: EMP004 | B6: Saeed Khan | C6: Supervisor | D6: ='Attendance Sheet'!AJ7 -> 26 | E6: ='Attendance Sheet'!AK7 -> 0 | F6: ='Attendance Sheet'!AL7 -> 4 | G6: =IF(C6="Driver", 25000, IF(C6="Supervisor", 45000, 55000)) -> 45000 | H6: =ROUND(G6/30, 0) -> 1500 | I6: =G6-(E6*H6) -> 45000 | J6: =IF(C6="Driver", D6*500, 0) -> 0 | K6: =I6+J6 -> 45000 | L6: 0 | M6: 0 | N6: 0 | O6: =K6-N6 -> 45000 | P6: Active
A7: EMP005 | B7: Moshtaq Khan | C7: Driver | D7: ='Attendance Sheet'!AJ8 -> 26 | E7: ='Attendance Sheet'!AK8 -> 0 | F7: ='Attendance Sheet'!AL8 -> 4 | G7: =IF(C7="Driver", 25000, IF(C7="Supervisor", 45000, 55000)) -> 25000 | H7: =ROUND(G7/30, 0) -> 833 | I7: =G7-(E7*H7) -> 25000 | J7: =IF(C7="Driver", D7*500, 0) -> 13000 | K7: =I7+J7 -> 38000 | L7: 0 | M7: 0 | N7: 0 | O7: =K7-N7 -> 38000 | P7: Active
A8: EMP006 | B8: Shahid | C8: Driver | D8: ='Attendance Sheet'!AJ9 -> 23 | E8: ='Attendance Sheet'!AK9 -> 3 | F8: ='Attendance Sheet'!AL9 -> 4 | G8: =IF(C8="Driver", 25000, IF(C8="Supervisor", 45000, 55000)) -> 25000 | H8: =ROUND(G8/30, 0) -> 833 | I8: =G8-(E8*H8) -> 22501 | J8: =IF(C8="Driver", D8*500, 0) -> 11500 | K8: =I8+J8 -> 34001 | L8: 0 | M8: 0 | N8: 0 | O8: =K8-N8 -> 34001 | P8: Active
A9: EMP007 | B9: Raju | C9: Driver | D9: ='Attendance Sheet'!AJ10 -> 26 | E9: ='Attendance Sheet'!AK10 -> 0 | F9: ='Attendance Sheet'!AL10 -> 4 | G9: =IF(C9="Driver", 25000, IF(C9="Supervisor", 45000, 55000)) -> 25000 | H9: =ROUND(G9/30, 0) -> 833 | I9: =G9-(E9*H9) -> 25000 | J9: =IF(C9="Driver", D9*500, 0) -> 13000 | K9: =I9+J9 -> 38000 | L9: 0 | M9: 0 | N9: 0 | O9: =K9-N9 -> 38000 | P9: Active
A10: EMP008 | B10: Umer Zada | C10: Driver | D10: ='Attendance Sheet'!AJ11 -> 26 | E10: ='Attendance Sheet'!AK11 -> 0 | F10: ='Attendance Sheet'!AL11 -> 4 | G10: =IF(C10="Driver", 25000, IF(C10="Supervisor", 45000, 55000)) -> 25000 | H10: =ROUND(G10/30, 0) -> 833 | I10: =G10-(E10*H10) -> 25000 | J10: =IF(C10="Driver", D10*500, 0) -> 13000 | K10: =I10+J10 -> 38000 | L10: 0 | M10: 0 | N10: 0 | O10: =K10-N10 -> 38000 | P10: Active
A11: EMP009 | B11: Israr Ahmed | C11: Driver | D11: ='Attendance Sheet'!AJ12 -> 26 | E11: ='Attendance Sheet'!AK12 -> 0 | F11: ='Attendance Sheet'!AL12 -> 4 | G11: =IF(C11="Driver", 25000, IF(C11="Supervisor", 45000, 55000)) -> 25000 | H11: =ROUND(G11/30, 0) -> 833 | I11: =G11-(E11*H11) -> 25000 | J11: =IF(C11="Driver", D11*500, 0) -> 13000 | K11: =I11+J11 -> 38000 | L11: 0 | M11: 0 | N11: 0 | O11: =K11-N11 -> 38000 | P11: Active
A12: EMP10 | B12: Abdul Rasheed | C12: Driver | D12: ='Attendance Sheet'!AJ13 -> 26 | E12: ='Attendance Sheet'!AK13 -> 0 | F12: ='Attendance Sheet'!AL13 -> 4 | G12: =IF(C12="Driver", 25000, IF(C12="Supervisor", 45000, 55000)) -> 25000 | H12: =ROUND(G12/30, 0) -> 833 | I12: =G12-(E12*H12) -> 25000 | J12: =IF(C12="Driver", D12*500, 0) -> 13000 | K12: =I12+J12 -> 38000 | L12: 0 | M12: 0 | N12: 0 | O12: =K12-N12 -> 38000 | P12: Active
A13: EMP11 | B13: Saad U Llah | C13: Driver | D13: ='Attendance Sheet'!AJ14 -> 22 | E13: ='Attendance Sheet'!AK14 -> 4 | F13: ='Attendance Sheet'!AL14 -> 4 | G13: =IF(C13="Driver", 25000, IF(C13="Supervisor", 45000, 55000)) -> 25000 | H13: =ROUND(G13/30, 0) -> 833 | I13: =G13-(E13*H13) -> 21668 | J13: =IF(C13="Driver", D13*500, 0) -> 11000 | K13: =I13+J13 -> 32668 | L13: 0 | M13: 0 | N13: 0 | O13: =K13-N13 -> 32668 | P13: Active
A14: EMP12 | B14: Khawas | C14: Driver | D14: ='Attendance Sheet'!AJ15 -> 26 | E14: ='Attendance Sheet'!AK15 -> 0 | F14: ='Attendance Sheet'!AL15 -> 4 | G14: =IF(C14="Driver", 25000, IF(C14="Supervisor", 45000, 55000)) -> 25000 | H14: =ROUND(G14/30, 0) -> 833 | I14: =G14-(E14*H14) -> 25000 | J14: =IF(C14="Driver", D14*500, 0) -> 13000 | K14: =I14+J14 -> 38000 | L14: 0 | M14: 0 | N14: 0 | O14: =K14-N14 -> 38000 | P14: Active
... A41: EMP39 | B41: Doulat Khan | C41: Driver | D41: ='Attendance Sheet'!AJ42 -> 20 | E41: ='Attendance Sheet'!AK42 -> 6 | F41: ='Attendance Sheet'!AL42 -> 4 | G41: =IF(C41="Driver", 25000, IF(C41="Supervisor", 45000, 55000)) -> 25000 | H41: =ROUND(G41/30, 0) -> 833 | I41: =G41-(E41*H41) -> 20002 | J41: =IF(C41="Driver", D41*500, 0) -> 10000 | K41: =I41+J41 -> 30002 | L41: 0 | M41: 0 | N41: 0 | O41: =K41-N41 -> 30002 | P41: Active
A42: EMP40 | C42: Driver | D42: ='Attendance Sheet'!AJ43 -> 24 | E42: ='Attendance Sheet'!AK43 -> 2 | F42: ='Attendance Sheet'!AL43 -> 4 | G42: =IF(C42="Driver", 25000, IF(C42="Supervisor", 45000, 55000)) -> 25000 | H42: =ROUND(G42/30, 0) -> 833 | I42: =G42-(E42*H42) -> 23334 | J42: =IF(C42="Driver", D42*500, 0) -> 12000 | K42: =I42+J42 -> 35334 | L42: 0 | M42: 0 | N42: 0 | O42: =K42-N42 -> 35334 | P42: Active
A43: EMP41 | B43: Noor Asgher | C43: Driver | D43: ='Attendance Sheet'!AJ44 -> 25 | E43: ='Attendance Sheet'!AK44 -> 1 | F43: ='Attendance Sheet'!AL44 -> 4 | G43: =IF(C43="Driver", 25000, IF(C43="Supervisor", 45000, 55000)) -> 25000 | H43: =ROUND(G43/30, 0) -> 833 | I43: =G43-(E43*H43) -> 24167 | J43: =IF(C43="Driver", D43*500, 0) -> 12500 | K43: =I43+J43 -> 36667 | L43: 0 | M43: 0 | N43: 0 | O43: =K43-N43 -> 36667 | P43: Active
A44: EMP42 | B44: Majeed | C44: Driver | D44: ='Attendance Sheet'!AJ45 -> 23 | E44: ='Attendance Sheet'!AK45 -> 3 | F44: ='Attendance Sheet'!AL45 -> 4 | G44: =IF(C44="Driver", 25000, IF(C44="Supervisor", 45000, 55000)) -> 25000 | H44: =ROUND(G44/30, 0) -> 833 | I44: =G44-(E44*H44) -> 22501 | J44: =IF(C44="Driver", D44*500, 0) -> 11500 | K44: =I44+J44 -> 34001 | L44: 0 | M44: 0 | N44: 0 | O44: =K44-N44 -> 34001 | P44: Active
A45: EMP43 | B45: Riaz Hussain | C45: Driver | D45: ='Attendance Sheet'!AJ46 -> 26 | E45: ='Attendance Sheet'!AK46 -> 0 | F45: ='Attendance Sheet'!AL46 -> 4 | G45: =IF(C45="Driver", 25000, IF(C45="Supervisor", 45000, 55000)) -> 25000 | H45: =ROUND(G45/30, 0) -> 833 | I45: =G45-(E45*H45) -> 25000 | J45: =IF(C45="Driver", D45*500, 0) -> 13000 | K45: =I45+J45 -> 38000 | L45: 0 | M45: 0 | N45: 0 | O45: =K45-N45 -> 38000 | P45: Active
A46: EMP44 | B46: Sultan | C46: Driver | D46: ='Attendance Sheet'!AJ47 -> 24 | E46: ='Attendance Sheet'!AK47 -> 2 | F46: ='Attendance Sheet'!AL47 -> 4 | G46: =IF(C46="Driver", 25000, IF(C46="Supervisor", 45000, 55000)) -> 25000 | H46: =ROUND(G46/30, 0) -> 833 | I46: =G46-(E46*H46) -> 23334 | J46: =IF(C46="Driver", D46*500, 0) -> 12000 | K46: =I46+J46 -> 35334 | L46: 0 | M46: 0 | N46: 0 | O46: =K46-N46 -> 35334 | P46: Active
A47: EMP45 | B47: Yasir | C47: Driver | D47: ='Attendance Sheet'!AJ48 -> 24 | E47: ='Attendance Sheet'!AK48 -> 2 | F47: ='Attendance Sheet'!AL48 -> 4 | G47: =IF(C47="Driver", 25000, IF(C47="Supervisor", 45000, 55000)) -> 25000 | H47: =ROUND(G47/30, 0) -> 833 | I47: =G47-(E47*H47) -> 23334 | J47: =IF(C47="Driver", D47*500, 0) -> 12000 | K47: =I47+J47 -> 35334 | L47: 0 | M47: 0 | N47: 0 | O47: =K47-N47 -> 35334 | P47: Active
A48: EMP46 | B48: Muhammad Khan | C48: Driver | D48: ='Attendance Sheet'!AJ49 -> 24 | E48: ='Attendance Sheet'!AK49 -> 2 | F48: ='Attendance Sheet'!AL49 -> 4 | G48: =IF(C48="Driver", 25000, IF(C48="Supervisor", 45000, 55000)) -> 25000 | H48: =ROUND(G48/30, 0) -> 833 | I48: =G48-(E48*H48) -> 23334 | J48: =IF(C48="Driver", D48*500, 0) -> 12000 | K48: =I48+J48 -> 35334 | L48: 0 | M48: 0 | N48: 0 | O48: =K48-N48 -> 35334 | P48: Active
A49: EMP47 | B49: Hammed | C49: Driver | D49: ='Attendance Sheet'!AJ50 -> 26 | E49: ='Attendance Sheet'!AK50 -> 0 | F49: ='Attendance Sheet'!AL50 -> 4 | G49: =IF(C49="Driver", 25000, IF(C49="Supervisor", 45000, 55000)) -> 25000 | H49: =ROUND(G49/30, 0) -> 833 | I49: =G49-(E49*H49) -> 25000 | J49: =IF(C49="Driver", D49*500, 0) -> 13000 | K49: =I49+J49 -> 38000 | L49: 0 | M49: 0 | N49: 0 | O49: =K49-N49 -> 38000 | P49: Active
A50: EMP48 | C50: Driver | D50: ='Attendance Sheet'!AJ51 -> 26 | E50: ='Attendance Sheet'!AK51 -> 0 | F50: ='Attendance Sheet'!AL51 -> 4 | G50: =IF(C50="Driver", 25000, IF(C50="Supervisor", 45000, 55000)) -> 25000 | H50: =ROUND(G50/30, 0) -> 833 | I50: =G50-(E50*H50) -> 25000 | J50: =IF(C50="Driver", D50*500, 0) -> 13000 | K50: =I50+J50 -> 38000 | L50: 0 | M50: 0 | N50: 0 | O50: =K50-N50 -> 38000 | P50: Active
A51: EMP49 | B51: Anwer | C51: Driver | D51: ='Attendance Sheet'!AJ52 -> 21 | E51: ='Attendance Sheet'!AK52 -> 5 | F51: ='Attendance Sheet'!AL52 -> 4 | G51: =IF(C51="Driver", 25000, IF(C51="Supervisor", 45000, 55000)) -> 25000 | H51: =ROUND(G51/30, 0) -> 833 | I51: =G51-(E51*H51) -> 20835 | J51: =IF(C51="Driver", D51*500, 0) -> 10500 | K51: =I51+J51 -> 31335 | L51: 0 | M51: 0 | N51: 0 | O51: =K51-N51 -> 31335 | P51: Active
A52: EMP50 | B52: Ismail | C52: Driver | D52: ='Attendance Sheet'!AJ53 -> 21 | E52: ='Attendance Sheet'!AK53 -> 5 | F52: ='Attendance Sheet'!AL53 -> 4 | G52: =IF(C52="Driver", 25000, IF(C52="Supervisor", 45000, 55000)) -> 25000 | H52: =ROUND(G52/30, 0) -> 833 | I52: =G52-(E52*H52) -> 20835 | J52: =IF(C52="Driver", D52*500, 0) -> 10500 | K52: =I52+J52 -> 31335 | L52: 0 | M52: 0 | N52: 0 | O52: =K52-N52 -> 31335 | P52: Active
A53: EMP51 | B53: Tahir | C53: Driver | D53: ='Attendance Sheet'!AJ54 -> 21 | E53: ='Attendance Sheet'!AK54 -> 5 | F53: ='Attendance Sheet'!AL54 -> 4 | G53: =IF(C53="Driver", 25000, IF(C53="Supervisor", 45000, 55000)) -> 25000 | H53: =ROUND(G53/30, 0) -> 833 | I53: =G53-(E53*H53) -> 20835 | J53: =IF(C53="Driver", D53*500, 0) -> 10500 | K53: =I53+J53 -> 31335 | L53: 0 | M53: 0 | N53: 0 | O53: =K53-N53 -> 31335 | P53: Active
A54: EMP52 | B54: Khan Aslam | C54: Driver | D54: ='Attendance Sheet'!AJ55 -> 25 | E54: ='Attendance Sheet'!AK55 -> 1 | F54: ='Attendance Sheet'!AL55 -> 4 | G54: =IF(C54="Driver", 25000, IF(C54="Supervisor", 45000, 55000)) -> 25000 | H54: =ROUND(G54/30, 0) -> 833 | I54: =G54-(E54*H54) -> 24167 | J54: =IF(C54="Driver", D54*500, 0) -> 12500 | K54: =I54+J54 -> 36667 | L54: 0 | M54: 0 | N54: 0 | O54: =K54-N54 -> 36667 | P54: Active
A55: EMP53 | B55: Nawab | C55: Driver | D55: ='Attendance Sheet'!AJ56 -> 25 | E55: ='Attendance Sheet'!AK56 -> 1 | F55: ='Attendance Sheet'!AL56 -> 4 | G55: =IF(C55="Driver", 25000, IF(C55="Supervisor", 45000, 55000)) -> 25000 | H55: =ROUND(G55/30, 0) -> 833 | I55: =G55-(E55*H55) -> 24167 | J55: =IF(C55="Driver", D55*500, 0) -> 12500 | K55: =I55+J55 -> 36667 | L55: 0 | M55: 0 | N55: 0 | O55: =K55-N55 -> 36667 | P55: Active
A56: EMP54 | B56: Ashger | C56: Driver | D56: ='Attendance Sheet'!AJ57 -> 25 | E56: ='Attendance Sheet'!AK57 -> 1 | F56: ='Attendance Sheet'!AL57 -> 4 | G56: =IF(C56="Driver", 25000, IF(C56="Supervisor", 45000, 55000)) -> 25000 | H56: =ROUND(G56/30, 0) -> 833 | I56: =G56-(E56*H56) -> 24167 | J56: =IF(C56="Driver", D56*500, 0) -> 12500 | K56: =I56+J56 -> 36667 | L56: 0 | M56: 0 | N56: 0 | O56: =K56-N56 -> 36667 | P56: Active
A57: EMP55 | B57: Bashir | C57: Driver | D57: ='Attendance Sheet'!AJ58 -> 18 | E57: ='Attendance Sheet'!AK58 -> 8 | F57: ='Attendance Sheet'!AL58 -> 4 | G57: =IF(C57="Driver", 25000, IF(C57="Supervisor", 45000, 55000)) -> 25000 | H57: =ROUND(G57/30, 0) -> 833 | I57: =G57-(E57*H57) -> 18336 | J57: =IF(C57="Driver", D57*500, 0) -> 9000 | K57: =I57+J57 -> 27336 | L57: 0 | M57: 0 | N57: 0 | O57: =K57-N57 -> 27336 | P57: Active
A58: EMP56 | B58: Khalil UR Rehman | C58: Driver | D58: ='Attendance Sheet'!AJ59 -> 20 | E58: ='Attendance Sheet'!AK59 -> 6 | F58: ='Attendance Sheet'!AL59 -> 4 | G58: =IF(C58="Driver", 25000, IF(C58="Supervisor", 45000, 55000)) -> 25000 | H58: =ROUND(G58/30, 0) -> 833 | I58: =G58-(E58*H58) -> 20002 | J58: =IF(C58="Driver", D58*500, 0) -> 10000 | K58: =I58+J58 -> 30002 | L58: 0 | M58: 0 | N58: 0 | O58: =K58-N58 -> 30002 | P58: Active
A59: EMP57 | B59: Gull Sher | C59: Driver | D59: ='Attendance Sheet'!AJ60 -> 13 | E59: ='Attendance Sheet'!AK60 -> 13 | F59: ='Attendance Sheet'!AL60 -> 4 | G59: =IF(C59="Driver", 25000, IF(C59="Supervisor", 45000, 55000)) -> 25000 | H59: =ROUND(G59/30, 0) -> 833 | I59: =G59-(E59*H59) -> 14171 | J59: =IF(C59="Driver", D59*500, 0) -> 6500 | K59: =I59+J59 -> 20671 | L59: 0 | M59: 0 | N59: 0 | O59: =K59-N59 -> 20671 | P59: Active
A60: EMP58 | D60: ='Attendance Sheet'!AJ61 -> 0 | E60: ='Attendance Sheet'!AK61 -> 0 | F60: ='Attendance Sheet'!AL61 -> 0 | G60: =IF(C60="Driver", 25000, IF(C60="Supervisor", 45000, 55000)) -> 55000 | H60: =ROUND(G60/30, 0) -> 1833 | I60: =G60-(E60*H60) -> 55000 | J60: =IF(C60="Driver", D60*500, 0) -> 0 | K60: =I60+J60 -> 55000 | L60: 0 | M60: 0 | N60: 0 | O60: =K60-N60 -> 55000
A61: EMP59 | D61: ='Attendance Sheet'!AJ62 -> 0 | E61: ='Attendance Sheet'!AK62 -> 0 | F61: ='Attendance Sheet'!AL62 -> 0 | G61: =IF(C61="Driver", 25000, IF(C61="Supervisor", 45000, 55000)) -> 55000 | H61: =ROUND(G61/30, 0) -> 1833 | I61: =G61-(E61*H61) -> 55000 | J61: =IF(C61="Driver", D61*500, 0) -> 0 | K61: =I61+J61 -> 55000 | L61: 0 | M61: 0 | N61: 0 | O61: =K61-N61 -> 55000
A62: EMP60 | D62: ='Attendance Sheet'!AJ63 -> 0 | E62: ='Attendance Sheet'!AK63 -> 0 | F62: ='Attendance Sheet'!AL63 -> 0 | G62: =IF(C62="Driver", 25000, IF(C62="Supervisor", 45000, 55000)) -> 55000 | H62: =ROUND(G62/30, 0) -> 1833 | I62: =G62-(E62*H62) -> 55000 | J62: =IF(C62="Driver", D62*500, 0) -> 0 | K62: =I62+J62 -> 55000 | L62: 0 | M62: 0 | N62: 0 | O62: =K62-N62 -> 55000
A63: EMP61 | D63: ='Attendance Sheet'!AJ64 -> 0 | E63: ='Attendance Sheet'!AK64 -> 0 | F63: ='Attendance Sheet'!AL64 -> 0 | G63: =IF(C63="Driver", 25000, IF(C63="Supervisor", 45000, 55000)) -> 55000 | H63: =ROUND(G63/30, 0) -> 1833 | I63: =G63-(E63*H63) -> 55000 | J63: =IF(C63="Driver", D63*500, 0) -> 0 | K63: =I63+J63 -> 55000 | L63: 0 | M63: 0 | N63: 0 | O63: =K63-N63 -> 55000
A64: EMP62 | D64: ='Attendance Sheet'!AJ65 -> 0 | E64: ='Attendance Sheet'!AK65 -> 0 | F64: ='Attendance Sheet'!AL65 -> 0 | G64: =IF(C64="Driver", 25000, IF(C64="Supervisor", 45000, 55000)) -> 55000 | H64: =ROUND(G64/30, 0) -> 1833 | I64: =G64-(E64*H64) -> 55000 | J64: =IF(C64="Driver", D64*500, 0) -> 0 | K64: =I64+J64 -> 55000 | L64: 0 | M64: 0 | N64: 0 | O64: =K64-N64 -> 55000
A65: EMP63 | D65: ='Attendance Sheet'!AJ66 -> 0 | E65: ='Attendance Sheet'!AK66 -> 0 | F65: ='Attendance Sheet'!AL66 -> 0 | G65: =IF(C65="Driver", 25000, IF(C65="Supervisor", 45000, 55000)) -> 55000 | H65: =ROUND(G65/30, 0) -> 1833 | I65: =G65-(E65*H65) -> 55000 | J65: =IF(C65="Driver", D65*500, 0) -> 0 | K65: =I65+J65 -> 55000 | L65: 0 | M65: 0 | N65: 0 | O65: =K65-N65 -> 55000
A66: EMP64 | D66: ='Attendance Sheet'!AJ67 -> 0 | E66: ='Attendance Sheet'!AK67 -> 0 | F66: ='Attendance Sheet'!AL67 -> 0 | G66: =IF(C66="Driver", 25000, IF(C66="Supervisor", 45000, 55000)) -> 55000 | H66: =ROUND(G66/30, 0) -> 1833 | I66: =G66-(E66*H66) -> 55000 | J66: =IF(C66="Driver", D66*500, 0) -> 0 | K66: =I66+J66 -> 55000 | L66: 0 | M66: 0 | N66: 0 | O66: =K66-N66 -> 55000
...

Sheet Attendance Sheet
A1: EMPLOYEE MONTHLY ATTENDANCE TRACKER
A2: Month | B2: Jun-26 | C2: Dates | D2: Deployed | E2: 1 | F2: 2 | G2: 3 | H2: 4 | I2: 5 | J2: 6 | K2: 7 | L2: 8 | M2: 9 | N2: 10 | O2: 11 | P2: 12 | Q2: 13 | R2: 14 | S2: 15 | T2: 16 | U2: 17 | V2: 18 | W2: 19 | X2: 20 | Y2: 21 | Z2: 22 | AA2: 23 | AB2: 24 | AC2: 25 | AD2: 26 | AE2: 27 | AF2: 28 | AG2: 29 | AH2: 30 | AI2: 31 | AJ2: Column1 | AK2: Column2 | AL2: Column3
A3: Emp ID | B3: Employee Name | C3: Designation | D3: Vehicle # | E3: Monday | F3: Tuesday | G3: Wednesday | H3: Thursday | I3: Friday | J3: Saturday | K3: Sunday | L3: Monday | M3: Tuesday | N3: Wednesday | O3: Thursday | P3: Friday | Q3: Saturday | R3: Sunday | S3: Monday | T3: Tuesday | U3: Wednesday | V3: Thursday | W3: Friday | X3: Saturday | Y3: Sunday | Z3: Monday | AA3: Tuesday | AB3: Wednesday | AC3: Thursday | AD3: Friday | AE3: Saturday | AF3: Sunday | AG3: Monday | AH3: Tuesday | AI3: Wednesday | AJ3: Total Present | AK3: Total Absent | AL3: Total Sunday
A4: EMP001 | B4: Shakeel Ayub | C4: Officer | E4: P | F4: P | G4: P | H4: P | I4: P | J4: P | K4: S | L4: P | M4: P | N4: P | O4: P | P4: P | Q4: P | R4: S | S4: P | T4: P | U4: P | V4: P | W4: P | X4: P | Y4: S | Z4: P | AA4: P | AB4: P | AC4: P | AD4: P | AE4: P | AF4: S | AG4: P | AH4: P | AJ4: =COUNTIF(E4:AI4, "P") -> 26 | AK4: =COUNTIF(E4:AI4, "A") -> 0 | AL4: =COUNTIF(E4:AI4, "S") -> 4
A5: EMP002 | B5: Kamal UL Haq | C5: Officer | E5: P | F5: P | G5: P | H5: P | I5: P | J5: P | K5: S | L5: P | M5: P | N5: P | O5: P | P5: P | Q5: P | R5: S | S5: P | T5: P | U5: P | V5: P | W5: P | X5: P | Y5: S | Z5: P | AA5: P | AB5: P | AC5: P | AD5: P | AE5: P | AF5: S | AG5: P | AH5: P | AJ5: =COUNTIF(E5:AI5, "P") -> 26 | AK5: =COUNTIF(E5:AI5, "A") -> 0 | AL5: =COUNTIF(E5:AI5, "S") -> 4
A6: EMP003 | B6: Ishaq Khan | C6: Super Visour At Kolsan | E6: P | F6: P | G6: P | H6: P | I6: P | J6: P | K6: S | L6: P | M6: P | N6: P | O6: P | P6: P | Q6: P | R6: S | S6: P | T6: P | U6: P | V6: P | W6: P | X6: P | Y6: S | Z6: P | AA6: P | AB6: P | AC6: P | AD6: P | AE6: P | AF6: S | AG6: P | AH6: P | AJ6: =COUNTIF(E6:AI6, "P") -> 26 | AK6: =COUNTIF(E6:AI6, "A") -> 0 | AL6: =COUNTIF(E6:AI6, "S") -> 4
A7: EMP004 | B7: Saeed Khan | C7: Super Visour At work shop | E7: P | F7: P | G7: P | H7: P | I7: P | J7: P | K7: S | L7: P | M7: P | N7: P | O7: P | P7: P | Q7: P | R7: S | S7: P | T7: P | U7: P | V7: P | W7: P | X7: P | Y7: S | Z7: P | AA7: P | AB7: P | AC7: P | AD7: P | AE7: P | AF7: S | AG7: P | AH7: P | AJ7: =COUNTIF(E7:AI7, "P") -> 26 | AK7: =COUNTIF(E7:AI7, "A") -> 0 | AL7: =COUNTIF(E7:AI7, "S") -> 4
A8: EMP005 | B8: Moshtaq Khan | C8: Diesel Boy | E8: P | F8: P | G8: P | H8: P | I8: P | J8: P | K8: S | L8: P | M8: P | N8: P | O8: P | P8: P | Q8: P | R8: S | S8: P | T8: P | U8: P | V8: P | W8: P | X8: P | Y8: S | Z8: P | AA8: P | AB8: P | AC8: P | AD8: P | AE8: P | AF8: S | AG8: P | AH8: P | AJ8: =COUNTIF(E8:AI8, "P") -> 26 | AK8: =COUNTIF(E8:AI8, "A") -> 0 | AL8: =COUNTIF(E8:AI8, "S") -> 4
A9: EMP006 | B9: Shahid | C9: Driver | D9: Jy-1212 | E9: P | F9: P | G9: P | H9: P | I9: P | J9: P | K9: S | L9: P | M9: A | N9: P | O9: P | P9: P | Q9: P | R9: S | S9: P | T9: P | U9: P | V9: P | W9: P | X9: P | Y9: S | Z9: A | AA9: A | AB9: p | AC9: p | AD9: p | AE9: p | AF9: S | AG9: P | AH9: P | AJ9: =COUNTIF(E9:AI9, "P") -> 23 | AK9: =COUNTIF(E9:AI9, "A") -> 3 | AL9: =COUNTIF(E9:AI9, "S") -> 4
A10: EMP007 | B10: Raju | C10: Driver | D10: Jy-1874 | E10: P | F10: P | G10: P | H10: P | I10: P | J10: P | K10: S | L10: P | M10: P | N10: P | O10: P | P10: P | Q10: P | R10: S | S10: P | T10: P | U10: P | V10: P | W10: P | X10: P | Y10: S | Z10: P | AA10: P | AB10: p | AC10: p | AD10: p | AE10: p | AF10: S | AG10: P | AH10: P | AJ10: =COUNTIF(E10:AI10, "P") -> 26 | AK10: =COUNTIF(E10:AI10, "A") -> 0 | AL10: =COUNTIF(E10:AI10, "S") -> 4
A11: EMP008 | B11: Umer Zada | C11: Driver | D11: Jy-5028 | E11: P | F11: P | G11: P | H11: P | I11: P | J11: P | K11: S | L11: P | M11: P | N11: P | O11: P | P11: P | Q11: P | R11: S | S11: P | T11: P | U11: P | V11: P | W11: P | X11: P | Y11: S | Z11: P | AA11: P | AB11: P | AC11: P | AD11: P | AE11: P | AF11: S | AG11: P | AH11: P | AJ11: =COUNTIF(E11:AI11, "P") -> 26 | AK11: =COUNTIF(E11:AI11, "A") -> 0 | AL11: =COUNTIF(E11:AI11, "S") -> 4
A12: EMP009 | B12: Israr Ahmed | C12: Driver | D12: Jz-0969 | E12: P | F12: P | G12: P | H12: P | I12: P | J12: P | K12: S | L12: P | M12: P | N12: P | O12: P | P12: P | Q12: P | R12: S | S12: P | T12: P | U12: P | V12: P | W12: P | X12: P | Y12: S | Z12: P | AA12: P | AB12: P | AC12: P | AD12: P | AE12: P | AF12: S | AG12: P | AH12: P | AJ12: =COUNTIF(E12:AI12, "P") -> 26 | AK12: =COUNTIF(E12:AI12, "A") -> 0 | AL12: =COUNTIF(E12:AI12, "S") -> 4
A13: EMP10 | B13: Abdul Rasheed | C13: Driver | D13: Jy-9317 | E13: P | F13: P | G13: P | H13: P | I13: P | J13: P | K13: S | L13: P | M13: P | N13: P | O13: P | P13: P | Q13: P | R13: S | S13: P | T13: P | U13: P | V13: P | W13: P | X13: P | Y13: S | Z13: P | AA13: P | AB13: P | AC13: P | AD13: P | AE13: P | AF13: S | AG13: P | AH13: P | AJ13: =COUNTIF(E13:AI13, "P") -> 26 | AK13: =COUNTIF(E13:AI13, "A") -> 0 | AL13: =COUNTIF(E13:AI13, "S") -> 4
A14: EMP11 | B14: Saad U Llah | C14: Driver | D14: Jy-0810 | E14: P | F14: P | G14: P | H14: P | I14: P | J14: P | K14: S | L14: P | M14: P | N14: P | O14: P | P14: A | Q14: A | R14: S | S14: P | T14: P | U14: P | V14: P | W14: A | X14: A | Y14: S | Z14: P | AA14: P | AB14: P | AC14: P | AD14: P | AE14: P | AF14: S | AG14: P | AH14: P | AJ14: =COUNTIF(E14:AI14, "P") -> 22 | AK14: =COUNTIF(E14:AI14, "A") -> 4 | AL14: =COUNTIF(E14:AI14, "S") -> 4
A15: EMP12 | B15: Khawas | C15: Driver | D15: Jy-4259 | E15: P | F15: P | G15: P | H15: P | I15: P | J15: P | K15: S | L15: P | M15: P | N15: P | O15: P | P15: P | Q15: P | R15: S | S15: P | T15: P | U15: P | V15: P | W15: P | X15: P | Y15: S | Z15: P | AA15: P | AB15: P | AC15: P | AD15: P | AE15: P | AF15: S | AG15: P | AH15: P | AJ15: =COUNTIF(E15:AI15, "P") -> 26 | AK15: =COUNTIF(E15:AI15, "A") -> 0 | AL15: =COUNTIF(E15:AI15, "S") -> 4
A16: EMP13 | B16: Ehid.Muhammad | C16: Driver | D16: Jx-7756 | E16: A | F16: A | G16: P | H16: P | I16: P | J16: P | K16: S | L16: P | M16: P | N16: P | O16: P | P16: P | Q16: P | R16: S | S16: P | T16: P | U16: P | V16: P | W16: P | X16: P | Y16: S | Z16: P | AA16: P | AB16: P | AC16: P | AD16: P | AE16: P | AF16: S | AG16: P | AH16: P | AJ16: =COUNTIF(E16:AI16, "P") -> 24 | AK16: =COUNTIF(E16:AI16, "A") -> 2 | AL16: =COUNTIF(E16:AI16, "S") -> 4
A17: EMP14 | B17: Shakoor | C17: Driver | D17: Jy-6094 | E17: P | F17: P | G17: P | H17: P | I17: P | J17: P | K17: S | L17: P | M17: P | N17: P | O17: P | P17: P | Q17: P | R17: S | S17: P | T17: P | U17: A | V17: P | W17: P | X17: P | Y17: S | Z17: P | AA17: P | AB17: P | AC17: P | AD17: P | AE17: P | AF17: S | AG17: P | AH17: P | AJ17: =COUNTIF(E17:AI17, "P") -> 25 | AK17: =COUNTIF(E17:AI17, "A") -> 1 | AL17: =COUNTIF(E17:AI17, "S") -> 4
A18: EMP15 | B18: Musawir | C18: Driver | D18: Jy-2629 | E18: P | F18: P | G18: P | H18: P | I18: P | J18: P | K18: S | L18: P | M18: P | N18: P | O18: P | P18: P | Q18: A | R18: S | S18: P | T18: P | U18: P | V18: P | W18: P | X18: P | Y18: S | Z18: P | AA18: P | AB18: P | AC18: P | AD18: P | AE18: P | AF18: S | AG18: P | AH18: P | AJ18: =COUNTIF(E18:AI18, "P") -> 25 | AK18: =COUNTIF(E18:AI18, "A") -> 1 | AL18: =COUNTIF(E18:AI18, "S") -> 4
A19: EMP16 | B19: Meer Hassan | C19: Driver | D19: Jx-7744 | E19: P | F19: P | G19: P | H19: P | I19: P | J19: A | K19: S | L19: P | M19: P | N19: P | O19: P | P19: P | Q19: P | R19: S | S19: P | T19: P | U19: P | V19: P | W19: A | X19: P | Y19: S | Z19: P | AA19: P | AB19: P | AC19: P | AD19: P | AE19: P | AF19: S | AG19: A | AH19: P | AJ19: =COUNTIF(E19:AI19, "P") -> 23 | AK19: =COUNTIF(E19:AI19, "A") -> 3 | AL19: =COUNTIF(E19:AI19, "S") -> 4
A20: EMP17 | B20: Imran | C20: Driver | D20: Jv-9988 | E20: P | F20: P | G20: P | H20: P | I20: A | J20: A | K20: S | L20: P | M20: P | N20: P | O20: P | P20: P | Q20: P | R20: S | S20: P | T20: P | U20: P | V20: P | W20: A | X20: A | Y20: S | Z20: P | AA20: P | AB20: P | AC20: P | AD20: P | AE20: P | AF20: S | AG20: P | AH20: P | AJ20: =COUNTIF(E20:AI20, "P") -> 22 | AK20: =COUNTIF(E20:AI20, "A") -> 4 | AL20: =COUNTIF(E20:AI20, "S") -> 4
... A25: EMP22 | B25: Gull Wali | C25: Driver | D25: Jz-0977 | E25: P | F25: P | G25: P | H25: P | I25: P | J25: P | K25: S | L25: P | M25: P | N25: P | O25: P | P25: P | Q25: P | R25: S | S25: P | T25: P | U25: P | V25: P | W25: P | X25: P | Y25: S | Z25: P | AA25: P | AB25: P | AC25: P | AD25: P | AE25: P | AF25: S | AG25: P | AH25: P | AJ25: =COUNTIF(E25:AI25, "P") -> 26 | AK25: =COUNTIF(E25:AI25, "A") -> 0 | AL25: =COUNTIF(E25:AI25, "S") -> 4
A26: EMP23 | B26: Zeeshan | C26: Driver | D26: Jz-8497 | E26: P | F26: P | G26: P | H26: P | I26: P | J26: P | K26: S | L26: A | M26: P | N26: P | O26: P | P26: P | R26: S | S26: P | T26: P | U26: P | V26: P | W26: P | X26: P | Y26: S | Z26: P | AA26: P | AB26: P | AC26: P | AD26: P | AE26: P | AF26: S | AG26: P | AH26: P | AJ26: =COUNTIF(E26:AI26, "P") -> 24 | AK26: =COUNTIF(E26:AI26, "A") -> 1 | AL26: =COUNTIF(E26:AI26, "S") -> 4
A27: EMP24 | B27: Ubaid | C27: Driver | D27: Jy-3618 | E27: P | F27: P | G27: A | H27: P | I27: P | J27: P | K27: S | L27: P | M27: P | N27: P | O27: P | P27: P | Q27: P | R27: S | S27: P | T27: P | U27: P | V27: P | W27: P | X27: P | Y27: S | Z27: A | AA27: P | AB27: P | AC27: P | AD27: P | AE27: P | AF27: S | AG27: P | AH27: P | AJ27: =COUNTIF(E27:AI27, "P") -> 24 | AK27: =COUNTIF(E27:AI27, "A") -> 2 | AL27: =COUNTIF(E27:AI27, "S") -> 4
A28: EMP25 | B28: Khyal Samanad | C28: Driver | D28: Tkz-301 | E28: P | F28: P | G28: P | H28: P | I28: P | J28: A | K28: S | L28: P | M28: P | N28: P | O28: P | P28: P | Q28: P | R28: S | S28: P | T28: P | U28: P | V28: P | W28: P | X28: P | Y28: S | Z28: P | AA28: P | AB28: P | AC28: P | AD28: P | AE28: P | AF28: S | AG28: P | AH28: P | AJ28: =COUNTIF(E28:AI28, "P") -> 25 | AK28: =COUNTIF(E28:AI28, "A") -> 1 | AL28: =COUNTIF(E28:AI28, "S") -> 4
A29: EMP26 | B29: Ishfaq | C29: Driver | D29: Jz-1328 | E29: P | F29: P | G29: P | H29: P | I29: P | J29: P | K29: S | L29: P | M29: P | N29: P | O29: P | P29: P | Q29: P | R29: S | S29: P | T29: P | U29: P | V29: P | W29: P | X29: P | Y29: S | Z29: P | AA29: P | AB29: P | AC29: P | AD29: P | AE29: P | AF29: S | AG29: P | AH29: P | AJ29: =COUNTIF(E29:AI29, "P") -> 26 | AK29: =COUNTIF(E29:AI29, "A") -> 0 | AL29: =COUNTIF(E29:AI29, "S") -> 4
A30: EMP27 | B30: Arbaz | C30: Driver | D30: Jw-5489 | E30: P | F30: P | G30: P | H30: P | I30: P | J30: P | K30: S | L30: P | M30: P | N30: P | O30: P | P30: P | Q30: P | R30: S | S30: P | T30: P | U30: P | V30: P | W30: P | X30: P | Y30: S | Z30: P | AA30: P | AB30: P | AC30: P | AD30: P | AE30: P | AF30: S | AG30: P | AH30: P | AJ30: =COUNTIF(E30:AI30, "P") -> 26 | AK30: =COUNTIF(E30:AI30, "A") -> 0 | AL30: =COUNTIF(E30:AI30, "S") -> 4
A31: EMP28 | B31: Shezad | C31: Driver | D31: Jw-5489 | E31: P | F31: P | G31: P | H31: P | I31: P | J31: P | K31: S | L31: P | M31: P | N31: P | O31: P | P31: P | Q31: P | R31: S | S31: P | T31: P | U31: P | V31: P | W31: P | X31: P | Y31: S | Z31: P | AA31: P | AB31: P | AC31: P | AD31: P | AE31: P | AF31: S | AG31: P | AH31: P | AJ31: =COUNTIF(E31:AI31, "P") -> 26 | AK31: =COUNTIF(E31:AI31, "A") -> 0 | AL31: =COUNTIF(E31:AI31, "S") -> 4
A32: EMP29 | B32: Shoukat | C32: Driver | D32: Jw-1656 | E32: P | F32: P | G32: P | H32: P | I32: P | J32: P | K32: S | L32: P | M32: P | N32: P | O32: P | P32: P | Q32: P | R32: S | S32: P | T32: P | U32: P | V32: P | W32: P | X32: P | Y32: S | Z32: P | AA32: P | AB32: P | AC32: P | AD32: P | AE32: P | AF32: S | AG32: P | AH32: P | AJ32: =COUNTIF(E32:AI32, "P") -> 26 | AK32: =COUNTIF(E32:AI32, "A") -> 0 | AL32: =COUNTIF(E32:AI32, "S") -> 4
A33: EMP30 | B33: Sami | C33: Driver | D33: Jw-1656 | E33: P | F33: P | G33: P | H33: P | I33: P | J33: P | K33: S | L33: P | M33: P | N33: P | O33: P | P33: P | Q33: P | R33: S | S33: P | T33: P | U33: P | V33: P | W33: P | X33: P | Y33: S | Z33: P | AA33: P | AB33: P | AC33: P | AD33: P | AE33: P | AF33: S | AG33: P | AH33: P | AJ33: =COUNTIF(E33:AI33, "P") -> 26 | AK33: =COUNTIF(E33:AI33, "A") -> 0 | AL33: =COUNTIF(E33:AI33, "S") -> 4
A34: EMP31 | B34: Noor Das | C34: Driver | D34: Jv-4735 | E34: P | F34: P | G34: P | H34: P | I34: P | J34: P | K34: S | L34: P | M34: P | N34: P | O34: P | P34: P | Q34: P | R34: S | S34: P | T34: P | U34: P | V34: P | W34: P | X34: P | Y34: S | Z34: P | AA34: P | AB34: P | AC34: P | AD34: P | AE34: P | AF34: S | AG34: P | AH34: P | AJ34: =COUNTIF(E34:AI34, "P") -> 26 | AK34: =COUNTIF(E34:AI34, "A") -> 0 | AL34: =COUNTIF(E34:AI34, "S") -> 4
A35: EMP32 | B35: Salman | C35: Driver | D35: Jv-4735 | E35: P | F35: P | G35: P | H35: P | I35: P | J35: P | K35: S | L35: P | M35: P | N35: P | O35: P | P35: P | Q35: P | R35: S | S35: P | T35: P | U35: P | V35: P | W35: P | X35: P | Y35: S | Z35: P | AA35: P | AB35: P | AC35: P | AD35: P | AE35: P | AF35: S | AG35: P | AH35: P | AJ35: =COUNTIF(E35:AI35, "P") -> 26 | AK35: =COUNTIF(E35:AI35, "A") -> 0 | AL35: =COUNTIF(E35:AI35, "S") -> 4
A36: EMP33 | B36: Irfan | C36: Driver | D36: Jw-6116 | E36: P | F36: P | G36: P | H36: P | I36: P | J36: P | K36: S | L36: P | M36: P | N36: P | O36: P | P36: P | Q36: P | R36: S | S36: P | T36: P | U36: P | V36: P | W36: P | X36: P | Y36: S | Z36: P | AA36: P | AB36: P | AC36: P | AD36: P | AE36: P | AF36: S | AG36: P | AH36: P | AJ36: =COUNTIF(E36:AI36, "P") -> 26 | AK36: =COUNTIF(E36:AI36, "A") -> 0 | AL36: =COUNTIF(E36:AI36, "S") -> 4
A37: EMP34 | B37: Zubair | C37: Driver | D37: Jw-6116 | E37: P | F37: P | G37: P | H37: P | I37: P | J37: P | K37: S | L37: P | M37: P | N37: P | O37: P | P37: P | Q37: P | R37: S | S37: P | T37: P | U37: P | V37: P | W37: P | X37: P | Y37: S | Z37: P | AA37: P | AB37: P | AC37: P | AD37: P | AE37: P | AF37: S | AG37: P | AH37: P | AJ37: =COUNTIF(E37:AI37, "P") -> 26 | AK37: =COUNTIF(E37:AI37, "A") -> 0 | AL37: =COUNTIF(E37:AI37, "S") -> 4
A38: EMP35 | B38: Saraj | C38: Driver | D38: Jv-3066 | E38: P | F38: P | G38: P | H38: P | I38: P | J38: P | K38: S | L38: P | M38: P | N38: P | O38: P | P38: A | Q38: P | R38: S | S38: P | T38: P | U38: A | V38: P | W38: P | X38: P | Y38: S | Z38: P | AA38: P | AB38: P | AC38: P | AD38: P | AE38: A | AF38: S | AG38: P | AH38: P | AJ38: =COUNTIF(E38:AI38, "P") -> 23 | AK38: =COUNTIF(E38:AI38, "A") -> 3 | AL38: =COUNTIF(E38:AI38, "S") -> 4
... A42: EMP39 | B42: Doulat Khan | C42: Driver | D42: Tkx-566 | E42: P | F42: P | G42: P | H42: P | I42: P | J42: A | K42: S | L42: P | M42: P | N42: P | O42: P | P42: P | Q42: P | R42: S | S42: P | T42: A | U42: A | V42: A | W42: A | X42: A | Y42: S | Z42: P | AA42: P | AB42: P | AC42: P | AD42: P | AE42: P | AF42: S | AG42: P | AH42: P | AJ42: =COUNTIF(E42:AI42, "P") -> 20 | AK42: =COUNTIF(E42:AI42, "A") -> 6 | AL42: =COUNTIF(E42:AI42, "S") -> 4
A43: EMP40 | C43: Driver | D43: Tkx-566 | E43: P | F43: P | G43: P | H43: P | I43: P | J43: P | K43: S | L43: P | M43: P | N43: P | O43: P | P43: P | Q43: P | R43: S | S43: P | T43: A | U43: A | V43: P | W43: P | X43: P | Y43: S | Z43: P | AA43: P | AB43: P | AC43: P | AD43: P | AE43: P | AF43: S | AG43: P | AH43: P | AJ43: =COUNTIF(E43:AI43, "P") -> 24 | AK43: =COUNTIF(E43:AI43, "A") -> 2 | AL43: =COUNTIF(E43:AI43, "S") -> 4
A44: EMP41 | B44: Noor Asgher | C44: Driver | D44: Jv-1692 | E44: A | F44: P | G44: P | H44: P | I44: P | J44: P | K44: S | L44: P | M44: P | N44: P | O44: P | P44: P | Q44: P | R44: S | S44: P | T44: P | U44: P | V44: P | W44: P | X44: P | Y44: S | Z44: P | AA44: P | AB44: P | AC44: P | AD44: P | AE44: P | AF44: S | AG44: P | AH44: P | AJ44: =COUNTIF(E44:AI44, "P") -> 25 | AK44: =COUNTIF(E44:AI44, "A") -> 1 | AL44: =COUNTIF(E44:AI44, "S") -> 4
A45: EMP42 | B45: Majeed | C45: Driver | D45: Jx-6504 | E45: P | F45: P | G45: A | H45: A | I45: A | J45: P | K45: S | L45: P | M45: P | N45: P | O45: P | P45: P | Q45: P | R45: S | S45: P | T45: P | U45: P | V45: P | W45: P | X45: P | Y45: S | Z45: P | AA45: P | AB45: P | AC45: P | AD45: P | AE45: P | AF45: S | AG45: P | AH45: P | AJ45: =COUNTIF(E45:AI45, "P") -> 23 | AK45: =COUNTIF(E45:AI45, "A") -> 3 | AL45: =COUNTIF(E45:AI45, "S") -> 4
A46: EMP43 | B46: Riaz Hussain | C46: Driver | D46: Jy-9968 | E46: P | F46: P | G46: P | H46: P | I46: P | J46: P | K46: S | L46: P | M46: P | N46: P | O46: P | P46: P | Q46: P | R46: S | S46: P | T46: P | U46: P | V46: P | W46: P | X46: P | Y46: S | Z46: P | AA46: P | AB46: P | AC46: P | AD46: P | AE46: P | AF46: S | AG46: P | AH46: P | AJ46: =COUNTIF(E46:AI46, "P") -> 26 | AK46: =COUNTIF(E46:AI46, "A") -> 0 | AL46: =COUNTIF(E46:AI46, "S") -> 4
A47: EMP44 | B47: Sultan | C47: Driver | D47: Jv-3066 | E47: P | F47: P | G47: P | H47: P | I47: P | J47: P | K47: S | L47: P | M47: P | N47: P | O47: P | P47: P | Q47: P | R47: S | S47: P | T47: P | U47: A | V47: P | W47: P | X47: P | Y47: S | Z47: P | AA47: P | AB47: P | AC47: P | AD47: P | AE47: A | AF47: S | AG47: P | AH47: P | AJ47: =COUNTIF(E47:AI47, "P") -> 24 | AK47: =COUNTIF(E47:AI47, "A") -> 2 | AL47: =COUNTIF(E47:AI47, "S") -> 4
...
